Workbook

Sheet TOC
A1: Stanmere Capital Partners I, L.P.
A2: Fund Accounting & Financial Reporting Model — master case workbook
A4: DISCLAIMER: This model is for instructional purposes only. Stanmere Capital Partners I, L.P. and every
A5: entity named in this workbook are fictional. Any resemblance to an actual fund, firm or company is coincidental.
A7: HOW IT WORKS: there are TWO hard-keyed layers. (1) Journal Entries — the general ledger. (2) Allocations — the
A8: partner-level split of each component, produced by the allocation engine from the ledger and the LPA rules.
A9: Everything else derives by formula. Changing a journal entry updates the trial balance, every statement and
A10: the waterfall automatically, but Allocations must be regenerated for investor-level reports to follow.
A11: Tie-Out Checks includes six allocation controls proving Allocations agrees to the ledger component by component.
A13: SCOPE: this is a FIXED INSTRUCTIONAL CASE, not a live production model. The figures are complete and
A14: internally consistent as presented. To extend the case, regenerate the Allocations tab from the ledger
A15: using the fund's allocation rules (see Fund Terms), then confirm all twenty-two controls still pass.
A17: COLOUR: blue = hard-keyed input · black = formula · green = link to another tab
A19: Group | B19: Tab | C19: What it does
A20: 1. Setup | B20: FS Cover | C20: Report cover, period and contacts
B21: Fund Terms | C21: Economic terms — every formula references these cells
B22: Partners | C22: Commitments, ownership %, admission close
B23: Chart of Accounts | C23: Account number, name, type, statement classification, normal balance, and a note on unused accounts
A24: 2. Ledger | B24: Journal Entries | C24: The complete general ledger. Hard-keyed layer 1 of 2.
B25: Allocations | C25: Partner-level split of each component. Hard-keyed layer 2 of 2.
B26: Trial Balance | C26: Account by year, built with SUMIFS over Journal Entries
A27: 3. Statements | B27: Balance Sheet | C27: Statement of Assets and Liabilities, ASC 946
B28: Income Statement | C28: Statement of Operations
B29: Changes in Partners' Capital | C29: Contributions, allocations, distributions, ending capital
B30: Cash Flow Statement | C30: Indirect method, gross purchases and disposals, reconciled to the change in cash, plus non-cash disclosure
B31: Financial Highlights | C31: LP-class ratios before and after carried interest, total return and since-inception IRR - required by ASC 946-205-50
B32: Schedule of Investments | C32: Positions at 31 December 2026, cost, fair value, % of net assets
A33: 4. Investors | B33: Investor Allocations | C33: Allocation grid across the GP and six limited partners
B34: Investor Capital Accounts | C34: Per-investor capital account statement with a selector
A35: 5. Economics | B35: Management Fee | C35: Quarterly fee schedule, basis, offsets
B36: Waterfall | C36: European whole-fund distribution waterfall and clawback test
B37: Performance | C37: Cash flows, DPI, RVPI, TVPI, IRR
A38: 6. Control | B38: Bank Reconciliation | C38: Cash per bank against cash per books, by quarter
B39: Tie-Out Checks | C39: Every cross-statement check as a live formula
A40: 7. Reference | B40: Glossary | C40: Technical terms used throughout

Sheet FS Cover
A1: Stanmere Capital Partners I, L.P.
A2: Annual Financial Report
A4: Fund | B4: Stanmere Capital Partners I, L.P.
A5: Entity type | B5: Delaware limited partnership
A6: General partner | B6: Stanmere Capital GP I, LLC
A7: Management company | B7: Stanmere Capital Management, LLC
A8: Period from | B8: 2019-01-02
A9: Period to | B9: 2030-06-30
A10: Basis of presentation | B10: Investment company accounting, ASC 946
A11: Auditor | B11: [Independent registered public accounting firm]
A12: Administrator | B12: [Fund administrator]
A13: Report date | B13: 2030-06-30
A15: Stanmere Capital Partners I, L.P. is a fictional fund created for instructional purposes.
A16: Any resemblance to an actual fund, firm or company is coincidental.

Sheet Fund Terms
A1: Fund Terms
A2: Blue cells are the economic terms. Formulas across the workbook reference these cells.
A4: Term | B4: Value | C4: Note
A5: Total commitments | B5: 250000000 | C5: Across three closes
A6: GP commitment | B6: 5000000 | C6: 2.0%; fee-free
A7: Initial close | B7: 2019-01-02 | C7: Close 1
A8: Second close | B8: 2019-10-01 | C8: Close 2
A9: Final close | B9: 2020-06-30 | C9: Close 3 — 18-month offering period
A10: Investment period ends | B10: 2025-06-30 | C10: 5 years from final close
A11: Term ends | B11: 2030-06-30 | C11: 10 years from final close
A12: Management fee rate | B12: 0.02 | C12: Of commitments during the investment period
A13: Management fee offset | B13: 1 | C13: Of monitoring and transaction fees
A14: Preferred return | B14: 0.08 | C14: Accrued quarterly on unreturned capital only; unpaid pref does not itself earn a return
A15: Carry catch-up | B15: 1 | C15: 100% until the carry side holds 20% of profits
A16: Carried interest | B16: 0.2 | C16: European whole-fund waterfall
A17: Equalization interest | B17: 0.08 | C17: Simple, annualized
A18: Organizational costs | B18: 1200000 | C18: Expensed as incurred, ASC 720-15-25-1
A19: Offering costs | B19: 900000 | C19: Charged against partners' capital at the first closing - ASC 946-20-25-5; the fund is not in continuous offering

Sheet Partners
A1: Partners and Commitments
A4: Partner | B4: Type | C4: Commitment | D4: % of fund | E4: Admitted
A5: Stanmere Capital GP I, LLC | B5: GP | C5: 5000000 | D5: =C5/$C$12 -> 0.02 | E5: Close 1
A6: Kelbrook State Retirement System | B6: LP | C6: 75000000 | D6: =C6/$C$12 -> 0.3 | E6: Close 1
A7: Ashfield University Endowment | B7: LP | C7: 40000000 | D7: =C7/$C$12 -> 0.16 | E7: Close 1
A8: Pellham Mutual Insurance Company | B8: LP | C8: 35000000 | D8: =C8/$C$12 -> 0.14 | E8: Close 2
A9: Lanternwood Partners, L.P. (fund-of-funds) | B9: LP | C9: 25000000 | D9: =C9/$C$12 -> 0.1 | E9: Close 2
A10: Ellinwood Family Holdings, LLC | B10: LP | C10: 30000000 | D10: =C10/$C$12 -> 0.12 | E10: Close 3
A11: Northmoor Trust Company | B11: LP | C11: 40000000 | D11: =C11/$C$12 -> 0.16 | E11: Close 3
A12: Total | C12: =SUM(C5:C11) -> 250000000 | D12: =SUM(D5:D11) -> 1

Sheet Chart of Accounts
A1: Chart of Accounts
A4: Account no. | B4: Account name | C4: Type | D4: Statement | E4: Normal balance | F4: Note
A5: 1000 | B5: Cash and cash equivalents | C5: Asset | D5: Balance Sheet | E5: Debit
A6: 1050 | B6: Subscriptions receivable | C6: Asset | D6: Balance Sheet | E6: Debit
A7: 1100 | B7: Investments, at cost | C7: Asset | D7: Balance Sheet | E7: Debit
A8: 1110 | B8: Unrealized appreciation/(depreciation) on investments | C8: Asset | D8: Balance Sheet | E8: Debit
A9: 1150 | B9: Investments, at cost - bridge notes | C9: Asset | D9: Balance Sheet | E9: Debit | F9: Bridge notes to portfolio companies. On conversion the balance is reclassified to 1100 at cost - no cash, no gain or loss.
A10: 1200 | B10: Interest and PIK receivable | C10: Asset | D10: Balance Sheet | E10: Debit | F10: Retired. PIK interest is capitalised into the principal of the Verrick note and is carried in account 1100, so this account holds no balance. Retained so the trial balance, the balance sheet and the cash flow statement keep a line for a fund that does settle interest in cash.
A11: 1250 | B11: Prepaid management fee | C11: Asset | D11: Balance Sheet | E11: Debit
A12: 1300 | B12: Deferred offering costs | C12: Asset | D12: Balance Sheet | E12: Debit | F12: Not used by Stanmere. Retained so module 1.3 can post the contrasting deferral treatment; it is carried through the trial balance, the balance sheet and the cash flow statement.
A13: 2000 | B13: Accounts payable and accrued expenses | C13: Liability | D13: Balance Sheet | E13: Credit
A14: 2100 | B14: Management fee payable | C14: Liability | D14: Balance Sheet | E14: Credit
A15: 2300 | B15: Subscription line payable | C15: Liability | D15: Balance Sheet | E15: Credit
A16: 2400 | B16: Distributions payable | C16: Liability | D16: Balance Sheet | E16: Credit
A17: 3000 | B17: Partners' capital - contributions | C17: Capital | D17: Partners' Capital | E17: Credit
A18: 3050 | B18: Partners' capital - offering costs charged against capital | C18: Capital | D18: Partners' Capital | E18: Debit | F18: Offering costs charged directly against partners' capital (ASC 946-20-25-5).
A19: 3100 | B19: Partners' capital - distributions | C19: Capital | D19: Partners' Capital | E19: Debit
A20: 3900 | B20: Partners' capital - accumulated results | C20: Capital | D20: Partners' Capital | E20: Credit | F20: Not used by Stanmere - never posted. Results stay in the income and expense accounts and are not closed to capital, and the cash flow statement's financing section is derived on that basis; a posting to 3900 would be missed there and break the cash tie-out.
A21: 4000 | B21: Interest income - PIK | C21: Income | D21: Income Statement | E21: Credit
A22: 4010 | B22: Interest income - other | C22: Income | D22: Income Statement | E22: Credit
A23: 4030 | B23: Other income - monitoring fees | C23: Income | D23: Income Statement | E23: Credit | F23: Not used by Stanmere. Monitoring fees are earned by the manager, not by the fund; under the LPA they reduce the management fee the fund owes (account 5010). The fund therefore records no monitoring fee income.
A24: 5000 | B24: Management fee | C24: Expense | D24: Income Statement | E24: Debit
A25: 5010 | B25: Management fee offset | C25: Expense | D25: Income Statement | E25: Credit | F25: The 100% offset of monitoring and transaction fees. Dr 2100 / Cr 5010 reduces both the fee payable and the fee expense; the manager then refunds the cash to the fund (Dr 1000 / Cr 2100).
A26: 5100 | B26: Organizational costs | C26: Expense | D26: Income Statement | E26: Debit
A27: 5110 | B27: Amortization of deferred offering costs | C27: Expense | D27: Income Statement | E27: Debit | F27: Not used by Stanmere. Retained for the module 1.3 contrast; it is carried through the trial balance and appears as its own line on the statement of operations.
A28: 5200 | B28: Professional fees - audit and tax | C28: Expense | D28: Income Statement | E28: Debit
A29: 5210 | B29: Professional fees - legal | C29: Expense | D29: Income Statement | E29: Debit
A30: 5300 | B30: Fund administration fees | C30: Expense | D30: Income Statement | E30: Debit
A31: 5400 | B31: Custody and bank fees | C31: Expense | D31: Income Statement | E31: Debit
A32: 5500 | B32: Interest expense - subscription line | C32: Expense | D32: Income Statement | E32: Debit
A33: 5600 | B33: Other fund expenses | C33: Expense | D33: Income Statement | E33: Debit
A34: 6000 | B34: Net realized gain/(loss) on investments | C34: Income | D34: Income Statement | E34: Credit
A35: 6100 | B35: Net change in unrealized appreciation/(depreciation) | C35: Income | D35: Income Statement | E35: Credit

Sheet Journal Entries
A1: Journal Entries — general ledger
A2: Hard-keyed layer 1 of 2. The general ledger. Trial balance, statements and waterfall derive from it.
A4: Trans. date | B4: Month end | C4: Quarter | D4: Acct | E4: Account name | F4: Curriculum module | G4: Debit | H4: Credit | I4: Amount (Dr-Cr) | J4: Per#
A5: 43555 | B5: 43555 | C5: 2019Q1 | D5: 1000 | E5: Cash and cash equivalents | F5: 2.1 capital calls | G5: 3100000 | I5: 3100000 | J5: 0
A6: 43555 | B6: 43555 | C6: 2019Q1 | D6: 3000 | E6: Partners' capital - contributions | F6: 2.1 capital calls | H6: 3100000 | I6: -3100000 | J6: 0
A7: 43555 | B7: 43555 | C7: 2019Q1 | D7: 5100 | E7: Organizational costs | F7: 1.3 org vs offering | G7: 1200000 | I7: 1200000 | J7: 0
A8: 43555 | B8: 43555 | C8: 2019Q1 | D8: 1000 | E8: Cash and cash equivalents | F8: 1.3 org vs offering | H8: 1200000 | I8: -1200000 | J8: 0
A9: 43555 | B9: 43555 | C9: 2019Q1 | D9: 3050 | E9: Partners' capital - offering costs charged against capital | F9: 1.3 org vs offering | G9: 900000 | I9: 900000 | J9: 0
A10: 43555 | B10: 43555 | C10: 2019Q1 | D10: 1000 | E10: Cash and cash equivalents | F10: 1.3 org vs offering | H10: 900000 | I10: -900000 | J10: 0
A11: 43555 | B11: 43555 | C11: 2019Q1 | D11: 5000 | E11: Management fee | F11: 2.2 management fees | G11: 575000 | I11: 575000 | J11: 0
A12: 43555 | B12: 43555 | C12: 2019Q1 | D12: 2100 | E12: Management fee payable | F12: 2.2 management fees | H12: 575000 | I12: -575000 | J12: 0
A13: 43555 | B13: 43555 | C13: 2019Q1 | D13: 2100 | E13: Management fee payable | F13: 2.2 management fees | G13: 575000 | I13: 575000 | J13: 0
A14: 43555 | B14: 43555 | C14: 2019Q1 | D14: 1000 | E14: Cash and cash equivalents | F14: 2.2 management fees | H14: 575000 | I14: -575000 | J14: 0
A15: 43555 | B15: 43555 | C15: 2019Q1 | D15: 5300 | E15: Fund administration fees | F15: 4.1 accruals & expenses | G15: 45000 | I15: 45000 | J15: 0
A16: 43555 | B16: 43555 | C16: 2019Q1 | D16: 5200 | E16: Professional fees - audit and tax | F16: 4.1 accruals & expenses | G16: 30000 | I16: 30000 | J16: 0
A17: 43555 | B17: 43555 | C17: 2019Q1 | D17: 5210 | E17: Professional fees - legal | F17: 4.1 accruals & expenses | G17: 35000 | I17: 35000 | J17: 0
A18: 43555 | B18: 43555 | C18: 2019Q1 | D18: 5400 | E18: Custody and bank fees | F18: 4.1 accruals & expenses | G18: 5000 | I18: 5000 | J18: 0
A19: 43555 | B19: 43555 | C19: 2019Q1 | D19: 5600 | E19: Other fund expenses | F19: 4.1 accruals & expenses | G19: 12000 | I19: 12000 | J19: 0
A20: 43555 | B20: 43555 | C20: 2019Q1 | D20: 2000 | E20: Accounts payable and accrued expenses | F20: 4.1 accruals & expenses | H20: 127000 | I20: -127000 | J20: 0
A21: 43555 | B21: 43555 | C21: 2019Q1 | D21: 2000 | E21: Accounts payable and accrued expenses | F21: 4.1 accruals & expenses | G21: 127000 | I21: 127000 | J21: 0
A22: 43555 | B22: 43555 | C22: 2019Q1 | D22: 1000 | E22: Cash and cash equivalents | F22: 4.1 accruals & expenses | H22: 127000 | I22: -127000 | J22: 0
A23: 43646 | B23: 43646 | C23: 2019Q2 | D23: 1000 | E23: Cash and cash equivalents | F23: 2.1 capital calls | G23: 42700000 | I23: 42700000 | J23: 1
A24: 43646 | B24: 43646 | C24: 2019Q2 | D24: 3000 | E24: Partners' capital - contributions | F24: 2.1 capital calls | H24: 42700000 | I24: -42700000 | J24: 1
A25: 43646 | B25: 43646 | C25: 2019Q2 | D25: 5000 | E25: Management fee | F25: 2.2 management fees | G25: 575000 | I25: 575000 | J25: 1
A26: 43646 | B26: 43646 | C26: 2019Q2 | D26: 2100 | E26: Management fee payable | F26: 2.2 management fees | H26: 575000 | I26: -575000 | J26: 1
A27: 43646 | B27: 43646 | C27: 2019Q2 | D27: 2100 | E27: Management fee payable | F27: 2.2 management fees | G27: 575000 | I27: 575000 | J27: 1
A28: 43646 | B28: 43646 | C28: 2019Q2 | D28: 1000 | E28: Cash and cash equivalents | F28: 2.2 management fees | H28: 575000 | I28: -575000 | J28: 1
A29: 43646 | B29: 43646 | C29: 2019Q2 | D29: 5300 | E29: Fund administration fees | F29: 4.1 accruals & expenses | G29: 45000 | I29: 45000 | J29: 1
A30: 43646 | B30: 43646 | C30: 2019Q2 | D30: 5200 | E30: Professional fees - audit and tax | F30: 4.1 accruals & expenses | G30: 30000 | I30: 30000 | J30: 1
A31: 43646 | B31: 43646 | C31: 2019Q2 | D31: 5210 | E31: Professional fees - legal | F31: 4.1 accruals & expenses | G31: 35000 | I31: 35000 | J31: 1
A32: 43646 | B32: 43646 | C32: 2019Q2 | D32: 5400 | E32: Custody and bank fees | F32: 4.1 accruals & expenses | G32: 5000 | I32: 5000 | J32: 1
A33: 43646 | B33: 43646 | C33: 2019Q2 | D33: 5600 | E33: Other fund expenses | F33: 4.1 accruals & expenses | G33: 12000 | I33: 12000 | J33: 1
A34: 43646 | B34: 43646 | C34: 2019Q2 | D34: 2000 | E34: Accounts payable and accrued expenses | F34: 4.1 accruals & expenses | H34: 127000 | I34: -127000 | J34: 1
A35: 43646 | B35: 43646 | C35: 2019Q2 | D35: 2000 | E35: Accounts payable and accrued expenses | F35: 4.1 accruals & expenses | G35: 127000 | I35: 127000 | J35: 1
A36: 43646 | B36: 43646 | C36: 2019Q2 | D36: 1000 | E36: Cash and cash equivalents | F36: 4.1 accruals & expenses | H36: 127000 | I36: -127000 | J36: 1
A37: 43646 | B37: 43646 | C37: 2019Q2 | D37: 1100 | E37: Investments, at cost | F37: 3.1 recording investments | G37: 42000000 | I37: 42000000 | J37: 1
A38: 43646 | B38: 43646 | C38: 2019Q2 | D38: 1000 | E38: Cash and cash equivalents | F38: 3.1 recording investments | H38: 42000000 | I38: -42000000 | J38: 1
A39: 43738 | B39: 43738 | C39: 2019Q3 | D39: 1000 | E39: Cash and cash equivalents | F39: 2.1 capital calls | G39: 700000 | I39: 700000 | J39: 2
A40: 43738 | B40: 43738 | C40: 2019Q3 | D40: 3000 | E40: Partners' capital - contributions | F40: 2.1 capital calls | H40: 700000 | I40: -700000 | J40: 2
A41: 43738 | B41: 43738 | C41: 2019Q3 | D41: 5000 | E41: Management fee | F41: 2.2 management fees | G41: 575000 | I41: 575000 | J41: 2
...

Sheet Trial Balance
A1: Trial Balance
A2: Cumulative net balance by account at each year end. SUMIFS over Journal Entries.
A4: Account no. | B4: Account name | C4: Normal | D4: FY2019 | E4: FY2020 | F4: FY2021 | G4: FY2022 | H4: FY2023 | I4: FY2024 | J4: FY2025 | K4: FY2026 | L4: FY2027 | M4: FY2028 | N4: FY2029 | O4: FY2030
A5: 1000 | B5: Cash and cash equivalents | C5: Dr | D5: =SUMIFS('Journal Entries'!$I$5:$I$785,'Journal Entries'!$D$5:$D$785,"1000",'Journal Entries'!$J$5:$J$785,"<=3") -> 292000 | E5: =SUMIFS('Journal Entries'!$I$5:$I$785,'Journal Entries'!$D$5:$D$785,"1000",'Journal Entries'!$J$5:$J$785,"<=7") -> 274000 | F5: =SUMIFS('Journal Entries'!$I$5:$I$785,'Journal Entries'!$D$5:$D$785,"1000",'Journal Entries'!$J$5:$J$785,"<=11") -> 2056000 | G5: =SUMIFS('Journal Entries'!$I$5:$I$785,'Journal Entries'!$D$5:$D$785,"1000",'Journal Entries'!$J$5:$J$785,"<=15") -> 1788000 | H5: =SUMIFS('Journal Entries'!$I$5:$I$785,'Journal Entries'!$D$5:$D$785,"1000",'Journal Entries'!$J$5:$J$785,"<=19") -> 1320000 | I5: =SUMIFS('Journal Entries'!$I$5:$I$785,'Journal Entries'!$D$5:$D$785,"1000",'Journal Entries'!$J$5:$J$785,"<=23") -> 1702000 | J5: =SUMIFS('Journal Entries'!$I$5:$I$785,'Journal Entries'!$D$5:$D$785,"1000",'Journal Entries'!$J$5:$J$785,"<=27") -> 1758000 | K5: =SUMIFS('Journal Entries'!$I$5:$I$785,'Journal Entries'!$D$5:$D$785,"1000",'Journal Entries'!$J$5:$J$785,"<=31") -> 304000 | L5: =SUMIFS('Journal Entries'!$I$5:$I$785,'Journal Entries'!$D$5:$D$785,"1000",'Journal Entries'!$J$5:$J$785,"<=35") -> 2075000 | M5: =SUMIFS('Journal Entries'!$I$5:$I$785,'Journal Entries'!$D$5:$D$785,"1000",'Journal Entries'!$J$5:$J$785,"<=39") -> 3058277.7 | N5: =SUMIFS('Journal Entries'!$I$5:$I$785,'Journal Entries'!$D$5:$D$785,"1000",'Journal Entries'!$J$5:$J$785,"<=43") -> 2734277.7 | O5: =SUMIFS('Journal Entries'!$I$5:$I$785,'Journal Entries'!$D$5:$D$785,"1000",'Journal Entries'!$J$5:$J$785,"<=45") -> 2.7939677e-09
A6: 1050 | B6: Subscriptions receivable | C6: Dr | D6: =SUMIFS('Journal Entries'!$I$5:$I$785,'Journal Entries'!$D$5:$D$785,"1050",'Journal Entries'!$J$5:$J$785,"<=3") -> 0 | E6: =SUMIFS('Journal Entries'!$I$5:$I$785,'Journal Entries'!$D$5:$D$785,"1050",'Journal Entries'!$J$5:$J$785,"<=7") -> 0 | F6: =SUMIFS('Journal Entries'!$I$5:$I$785,'Journal Entries'!$D$5:$D$785,"1050",'Journal Entries'!$J$5:$J$785,"<=11") -> 0 | G6: =SUMIFS('Journal Entries'!$I$5:$I$785,'Journal Entries'!$D$5:$D$785,"1050",'Journal Entries'!$J$5:$J$785,"<=15") -> 0 | H6: =SUMIFS('Journal Entries'!$I$5:$I$785,'Journal Entries'!$D$5:$D$785,"1050",'Journal Entries'!$J$5:$J$785,"<=19") -> 0 | I6: =SUMIFS('Journal Entries'!$I$5:$I$785,'Journal Entries'!$D$5:$D$785,"1050",'Journal Entries'!$J$5:$J$785,"<=23") -> 0 | J6: =SUMIFS('Journal Entries'!$I$5:$I$785,'Journal Entries'!$D$5:$D$785,"1050",'Journal Entries'!$J$5:$J$785,"<=27") -> 0 | K6: =SUMIFS('Journal Entries'!$I$5:$I$785,'Journal Entries'!$D$5:$D$785,"1050",'Journal Entries'!$J$5:$J$785,"<=31") -> 0 | L6: =SUMIFS('Journal Entries'!$I$5:$I$785,'Journal Entries'!$D$5:$D$785,"1050",'Journal Entries'!$J$5:$J$785,"<=35") -> 0 | M6: =SUMIFS('Journal Entries'!$I$5:$I$785,'Journal Entries'!$D$5:$D$785,"1050",'Journal Entries'!$J$5:$J$785,"<=39") -> 0 | N6: =SUMIFS('Journal Entries'!$I$5:$I$785,'Journal Entries'!$D$5:$D$785,"1050",'Journal Entries'!$J$5:$J$785,"<=43") -> 0 | O6: =SUMIFS('Journal Entries'!$I$5:$I$785,'Journal Entries'!$D$5:$D$785,"1050",'Journal Entries'!$J$5:$J$785,"<=45") -> 0
A7: 1100 | B7: Investments, at cost | C7: Dr | D7: =SUMIFS('Journal Entries'!$I$5:$I$785,'Journal Entries'!$D$5:$D$785,"1100",'Journal Entries'!$J$5:$J$785,"<=3") -> 42000000 | E7: =SUMIFS('Journal Entries'!$I$5:$I$785,'Journal Entries'!$D$5:$D$785,"1100",'Journal Entries'!$J$5:$J$785,"<=7") -> 95750000 | F7: =SUMIFS('Journal Entries'!$I$5:$I$785,'Journal Entries'!$D$5:$D$785,"1100",'Journal Entries'!$J$5:$J$785,"<=11") -> 145000000 | G7: =SUMIFS('Journal Entries'!$I$5:$I$785,'Journal Entries'!$D$5:$D$785,"1100",'Journal Entries'!$J$5:$J$785,"<=15") -> 172298178 | H7: =SUMIFS('Journal Entries'!$I$5:$I$785,'Journal Entries'!$D$5:$D$785,"1100",'Journal Entries'!$J$5:$J$785,"<=19") -> 1.8321823e+08 | I7: =SUMIFS('Journal Entries'!$I$5:$I$785,'Journal Entries'!$D$5:$D$785,"1100",'Journal Entries'!$J$5:$J$785,"<=23") -> 1.3537927e+08 | J7: =SUMIFS('Journal Entries'!$I$5:$I$785,'Journal Entries'!$D$5:$D$785,"1100",'Journal Entries'!$J$5:$J$785,"<=27") -> 1.1381154e+08 | K7: =SUMIFS('Journal Entries'!$I$5:$I$785,'Journal Entries'!$D$5:$D$785,"1100",'Journal Entries'!$J$5:$J$785,"<=31") -> 1.1654908e+08 | L7: =SUMIFS('Journal Entries'!$I$5:$I$785,'Journal Entries'!$D$5:$D$785,"1100",'Journal Entries'!$J$5:$J$785,"<=35") -> 84630211 | M7: =SUMIFS('Journal Entries'!$I$5:$I$785,'Journal Entries'!$D$5:$D$785,"1100",'Journal Entries'!$J$5:$J$785,"<=39") -> 18000000 | N7: =SUMIFS('Journal Entries'!$I$5:$I$785,'Journal Entries'!$D$5:$D$785,"1100",'Journal Entries'!$J$5:$J$785,"<=43") -> 2.6077032e-08 | O7: =SUMIFS('Journal Entries'!$I$5:$I$785,'Journal Entries'!$D$5:$D$785,"1100",'Journal Entries'!$J$5:$J$785,"<=45") -> 2.6077032e-08
A8: 1110 | B8: Unrealized appreciation/(depreciation) on investments | C8: Dr | D8: =SUMIFS('Journal Entries'!$I$5:$I$785,'Journal Entries'!$D$5:$D$785,"1110",'Journal Entries'!$J$5:$J$785,"<=3") -> 1500000 | E8: =SUMIFS('Journal Entries'!$I$5:$I$785,'Journal Entries'!$D$5:$D$785,"1110",'Journal Entries'!$J$5:$J$785,"<=7") -> 9000000 | F8: =SUMIFS('Journal Entries'!$I$5:$I$785,'Journal Entries'!$D$5:$D$785,"1110",'Journal Entries'!$J$5:$J$785,"<=11") -> 39000000 | G8: =SUMIFS('Journal Entries'!$I$5:$I$785,'Journal Entries'!$D$5:$D$785,"1110",'Journal Entries'!$J$5:$J$785,"<=15") -> 35000000 | H8: =SUMIFS('Journal Entries'!$I$5:$I$785,'Journal Entries'!$D$5:$D$785,"1110",'Journal Entries'!$J$5:$J$785,"<=19") -> 66000000 | I8: =SUMIFS('Journal Entries'!$I$5:$I$785,'Journal Entries'!$D$5:$D$785,"1110",'Journal Entries'!$J$5:$J$785,"<=23") -> 51000000 | J8: =SUMIFS('Journal Entries'!$I$5:$I$785,'Journal Entries'!$D$5:$D$785,"1110",'Journal Entries'!$J$5:$J$785,"<=27") -> 62500000 | K8: =SUMIFS('Journal Entries'!$I$5:$I$785,'Journal Entries'!$D$5:$D$785,"1110",'Journal Entries'!$J$5:$J$785,"<=31") -> 78000000 | L8: =SUMIFS('Journal Entries'!$I$5:$I$785,'Journal Entries'!$D$5:$D$785,"1110",'Journal Entries'!$J$5:$J$785,"<=35") -> 64000000 | M8: =SUMIFS('Journal Entries'!$I$5:$I$785,'Journal Entries'!$D$5:$D$785,"1110",'Journal Entries'!$J$5:$J$785,"<=39") -> 28000000 | N8: =SUMIFS('Journal Entries'!$I$5:$I$785,'Journal Entries'!$D$5:$D$785,"1110",'Journal Entries'!$J$5:$J$785,"<=43") -> 0 | O8: =SUMIFS('Journal Entries'!$I$5:$I$785,'Journal Entries'!$D$5:$D$785,"1110",'Journal Entries'!$J$5:$J$785,"<=45") -> 0
A9: 1150 | B9: Investments, at cost - bridge notes | C9: Dr | D9: =SUMIFS('Journal Entries'!$I$5:$I$785,'Journal Entries'!$D$5:$D$785,"1150",'Journal Entries'!$J$5:$J$785,"<=3") -> 0 | E9: =SUMIFS('Journal Entries'!$I$5:$I$785,'Journal Entries'!$D$5:$D$785,"1150",'Journal Entries'!$J$5:$J$785,"<=7") -> 1250000 | F9: =SUMIFS('Journal Entries'!$I$5:$I$785,'Journal Entries'!$D$5:$D$785,"1150",'Journal Entries'!$J$5:$J$785,"<=11") -> 0 | G9: =SUMIFS('Journal Entries'!$I$5:$I$785,'Journal Entries'!$D$5:$D$785,"1150",'Journal Entries'!$J$5:$J$785,"<=15") -> 0 | H9: =SUMIFS('Journal Entries'!$I$5:$I$785,'Journal Entries'!$D$5:$D$785,"1150",'Journal Entries'!$J$5:$J$785,"<=19") -> 0 | I9: =SUMIFS('Journal Entries'!$I$5:$I$785,'Journal Entries'!$D$5:$D$785,"1150",'Journal Entries'!$J$5:$J$785,"<=23") -> 0 | J9: =SUMIFS('Journal Entries'!$I$5:$I$785,'Journal Entries'!$D$5:$D$785,"1150",'Journal Entries'!$J$5:$J$785,"<=27") -> 0 | K9: =SUMIFS('Journal Entries'!$I$5:$I$785,'Journal Entries'!$D$5:$D$785,"1150",'Journal Entries'!$J$5:$J$785,"<=31") -> 0 | L9: =SUMIFS('Journal Entries'!$I$5:$I$785,'Journal Entries'!$D$5:$D$785,"1150",'Journal Entries'!$J$5:$J$785,"<=35") -> 0 | M9: =SUMIFS('Journal Entries'!$I$5:$I$785,'Journal Entries'!$D$5:$D$785,"1150",'Journal Entries'!$J$5:$J$785,"<=39") -> 0 | N9: =SUMIFS('Journal Entries'!$I$5:$I$785,'Journal Entries'!$D$5:$D$785,"1150",'Journal Entries'!$J$5:$J$785,"<=43") -> 0 | O9: =SUMIFS('Journal Entries'!$I$5:$I$785,'Journal Entries'!$D$5:$D$785,"1150",'Journal Entries'!$J$5:$J$785,"<=45") -> 0
A10: 1200 | B10: Interest and PIK receivable | C10: Dr | D10: =SUMIFS('Journal Entries'!$I$5:$I$785,'Journal Entries'!$D$5:$D$785,"1200",'Journal Entries'!$J$5:$J$785,"<=3") -> 0 | E10: =SUMIFS('Journal Entries'!$I$5:$I$785,'Journal Entries'!$D$5:$D$785,"1200",'Journal Entries'!$J$5:$J$785,"<=7") -> 0 | F10: =SUMIFS('Journal Entries'!$I$5:$I$785,'Journal Entries'!$D$5:$D$785,"1200",'Journal Entries'!$J$5:$J$785,"<=11") -> 0 | G10: =SUMIFS('Journal Entries'!$I$5:$I$785,'Journal Entries'!$D$5:$D$785,"1200",'Journal Entries'!$J$5:$J$785,"<=15") -> 0 | H10: =SUMIFS('Journal Entries'!$I$5:$I$785,'Journal Entries'!$D$5:$D$785,"1200",'Journal Entries'!$J$5:$J$785,"<=19") -> 0 | I10: =SUMIFS('Journal Entries'!$I$5:$I$785,'Journal Entries'!$D$5:$D$785,"1200",'Journal Entries'!$J$5:$J$785,"<=23") -> 0 | J10: =SUMIFS('Journal Entries'!$I$5:$I$785,'Journal Entries'!$D$5:$D$785,"1200",'Journal Entries'!$J$5:$J$785,"<=27") -> 0 | K10: =SUMIFS('Journal Entries'!$I$5:$I$785,'Journal Entries'!$D$5:$D$785,"1200",'Journal Entries'!$J$5:$J$785,"<=31") -> 0 | L10: =SUMIFS('Journal Entries'!$I$5:$I$785,'Journal Entries'!$D$5:$D$785,"1200",'Journal Entries'!$J$5:$J$785,"<=35") -> 0 | M10: =SUMIFS('Journal Entries'!$I$5:$I$785,'Journal Entries'!$D$5:$D$785,"1200",'Journal Entries'!$J$5:$J$785,"<=39") -> 0 | N10: =SUMIFS('Journal Entries'!$I$5:$I$785,'Journal Entries'!$D$5:$D$785,"1200",'Journal Entries'!$J$5:$J$785,"<=43") -> 0 | O10: =SUMIFS('Journal Entries'!$I$5:$I$785,'Journal Entries'!$D$5:$D$785,"1200",'Journal Entries'!$J$5:$J$785,"<=45") -> 0
A11: 1250 | B11: Prepaid management fee | C11: Dr | D11: =SUMIFS('Journal Entries'!$I$5:$I$785,'Journal Entries'!$D$5:$D$785,"1250",'Journal Entries'!$J$5:$J$785,"<=3") -> 0 | E11: =SUMIFS('Journal Entries'!$I$5:$I$785,'Journal Entries'!$D$5:$D$785,"1250",'Journal Entries'!$J$5:$J$785,"<=7") -> 0 | F11: =SUMIFS('Journal Entries'!$I$5:$I$785,'Journal Entries'!$D$5:$D$785,"1250",'Journal Entries'!$J$5:$J$785,"<=11") -> 0 | G11: =SUMIFS('Journal Entries'!$I$5:$I$785,'Journal Entries'!$D$5:$D$785,"1250",'Journal Entries'!$J$5:$J$785,"<=15") -> 0 | H11: =SUMIFS('Journal Entries'!$I$5:$I$785,'Journal Entries'!$D$5:$D$785,"1250",'Journal Entries'!$J$5:$J$785,"<=19") -> 0 | I11: =SUMIFS('Journal Entries'!$I$5:$I$785,'Journal Entries'!$D$5:$D$785,"1250",'Journal Entries'!$J$5:$J$785,"<=23") -> 0 | J11: =SUMIFS('Journal Entries'!$I$5:$I$785,'Journal Entries'!$D$5:$D$785,"1250",'Journal Entries'!$J$5:$J$785,"<=27") -> 0 | K11: =SUMIFS('Journal Entries'!$I$5:$I$785,'Journal Entries'!$D$5:$D$785,"1250",'Journal Entries'!$J$5:$J$785,"<=31") -> 0 | L11: =SUMIFS('Journal Entries'!$I$5:$I$785,'Journal Entries'!$D$5:$D$785,"1250",'Journal Entries'!$J$5:$J$785,"<=35") -> 0 | M11: =SUMIFS('Journal Entries'!$I$5:$I$785,'Journal Entries'!$D$5:$D$785,"1250",'Journal Entries'!$J$5:$J$785,"<=39") -> 0 | N11: =SUMIFS('Journal Entries'!$I$5:$I$785,'Journal Entries'!$D$5:$D$785,"1250",'Journal Entries'!$J$5:$J$785,"<=43") -> 0 | O11: =SUMIFS('Journal Entries'!$I$5:$I$785,'Journal Entries'!$D$5:$D$785,"1250",'Journal Entries'!$J$5:$J$785,"<=45") -> 0
A12: 1300 | B12: Deferred offering costs | C12: Dr | D12: =SUMIFS('Journal Entries'!$I$5:$I$785,'Journal Entries'!$D$5:$D$785,"1300",'Journal Entries'!$J$5:$J$785,"<=3") -> 0 | E12: =SUMIFS('Journal Entries'!$I$5:$I$785,'Journal Entries'!$D$5:$D$785,"1300",'Journal Entries'!$J$5:$J$785,"<=7") -> 0 | F12: =SUMIFS('Journal Entries'!$I$5:$I$785,'Journal Entries'!$D$5:$D$785,"1300",'Journal Entries'!$J$5:$J$785,"<=11") -> 0 | G12: =SUMIFS('Journal Entries'!$I$5:$I$785,'Journal Entries'!$D$5:$D$785,"1300",'Journal Entries'!$J$5:$J$785,"<=15") -> 0 | H12: =SUMIFS('Journal Entries'!$I$5:$I$785,'Journal Entries'!$D$5:$D$785,"1300",'Journal Entries'!$J$5:$J$785,"<=19") -> 0 | I12: =SUMIFS('Journal Entries'!$I$5:$I$785,'Journal Entries'!$D$5:$D$785,"1300",'Journal Entries'!$J$5:$J$785,"<=23") -> 0 | J12: =SUMIFS('Journal Entries'!$I$5:$I$785,'Journal Entries'!$D$5:$D$785,"1300",'Journal Entries'!$J$5:$J$785,"<=27") -> 0 | K12: =SUMIFS('Journal Entries'!$I$5:$I$785,'Journal Entries'!$D$5:$D$785,"1300",'Journal Entries'!$J$5:$J$785,"<=31") -> 0 | L12: =SUMIFS('Journal Entries'!$I$5:$I$785,'Journal Entries'!$D$5:$D$785,"1300",'Journal Entries'!$J$5:$J$785,"<=35") -> 0 | M12: =SUMIFS('Journal Entries'!$I$5:$I$785,'Journal Entries'!$D$5:$D$785,"1300",'Journal Entries'!$J$5:$J$785,"<=39") -> 0 | N12: =SUMIFS('Journal Entries'!$I$5:$I$785,'Journal Entries'!$D$5:$D$785,"1300",'Journal Entries'!$J$5:$J$785,"<=43") -> 0 | O12: =SUMIFS('Journal Entries'!$I$5:$I$785,'Journal Entries'!$D$5:$D$785,"1300",'Journal Entries'!$J$5:$J$785,"<=45") -> 0
A13: 2000 | B13: Accounts payable and accrued expenses | C13: Cr | D13: =SUMIFS('Journal Entries'!$I$5:$I$785,'Journal Entries'!$D$5:$D$785,"2000",'Journal Entries'!$J$5:$J$785,"<=3") -> 0 | E13: =SUMIFS('Journal Entries'!$I$5:$I$785,'Journal Entries'!$D$5:$D$785,"2000",'Journal Entries'!$J$5:$J$785,"<=7") -> 0 | F13: =SUMIFS('Journal Entries'!$I$5:$I$785,'Journal Entries'!$D$5:$D$785,"2000",'Journal Entries'!$J$5:$J$785,"<=11") -> 0 | G13: =SUMIFS('Journal Entries'!$I$5:$I$785,'Journal Entries'!$D$5:$D$785,"2000",'Journal Entries'!$J$5:$J$785,"<=15") -> 0 | H13: =SUMIFS('Journal Entries'!$I$5:$I$785,'Journal Entries'!$D$5:$D$785,"2000",'Journal Entries'!$J$5:$J$785,"<=19") -> 0 | I13: =SUMIFS('Journal Entries'!$I$5:$I$785,'Journal Entries'!$D$5:$D$785,"2000",'Journal Entries'!$J$5:$J$785,"<=23") -> 0 | J13: =SUMIFS('Journal Entries'!$I$5:$I$785,'Journal Entries'!$D$5:$D$785,"2000",'Journal Entries'!$J$5:$J$785,"<=27") -> 0 | K13: =SUMIFS('Journal Entries'!$I$5:$I$785,'Journal Entries'!$D$5:$D$785,"2000",'Journal Entries'!$J$5:$J$785,"<=31") -> 0 | L13: =SUMIFS('Journal Entries'!$I$5:$I$785,'Journal Entries'!$D$5:$D$785,"2000",'Journal Entries'!$J$5:$J$785,"<=35") -> 0 | M13: =SUMIFS('Journal Entries'!$I$5:$I$785,'Journal Entries'!$D$5:$D$785,"2000",'Journal Entries'!$J$5:$J$785,"<=39") -> 0 | N13: =SUMIFS('Journal Entries'!$I$5:$I$785,'Journal Entries'!$D$5:$D$785,"2000",'Journal Entries'!$J$5:$J$785,"<=43") -> 0 | O13: =SUMIFS('Journal Entries'!$I$5:$I$785,'Journal Entries'!$D$5:$D$785,"2000",'Journal Entries'!$J$5:$J$785,"<=45") -> 0
A14: 2100 | B14: Management fee payable | C14: Cr | D14: =SUMIFS('Journal Entries'!$I$5:$I$785,'Journal Entries'!$D$5:$D$785,"2100",'Journal Entries'!$J$5:$J$785,"<=3") -> 0 | E14: =SUMIFS('Journal Entries'!$I$5:$I$785,'Journal Entries'!$D$5:$D$785,"2100",'Journal Entries'!$J$5:$J$785,"<=7") -> 0 | F14: =SUMIFS('Journal Entries'!$I$5:$I$785,'Journal Entries'!$D$5:$D$785,"2100",'Journal Entries'!$J$5:$J$785,"<=11") -> 0 | G14: =SUMIFS('Journal Entries'!$I$5:$I$785,'Journal Entries'!$D$5:$D$785,"2100",'Journal Entries'!$J$5:$J$785,"<=15") -> 0 | H14: =SUMIFS('Journal Entries'!$I$5:$I$785,'Journal Entries'!$D$5:$D$785,"2100",'Journal Entries'!$J$5:$J$785,"<=19") -> 0 | I14: =SUMIFS('Journal Entries'!$I$5:$I$785,'Journal Entries'!$D$5:$D$785,"2100",'Journal Entries'!$J$5:$J$785,"<=23") -> 0 | J14: =SUMIFS('Journal Entries'!$I$5:$I$785,'Journal Entries'!$D$5:$D$785,"2100",'Journal Entries'!$J$5:$J$785,"<=27") -> 0 | K14: =SUMIFS('Journal Entries'!$I$5:$I$785,'Journal Entries'!$D$5:$D$785,"2100",'Journal Entries'!$J$5:$J$785,"<=31") -> 0 | L14: =SUMIFS('Journal Entries'!$I$5:$I$785,'Journal Entries'!$D$5:$D$785,"2100",'Journal Entries'!$J$5:$J$785,"<=35") -> 0 | M14: =SUMIFS('Journal Entries'!$I$5:$I$785,'Journal Entries'!$D$5:$D$785,"2100",'Journal Entries'!$J$5:$J$785,"<=39") -> 0 | N14: =SUMIFS('Journal Entries'!$I$5:$I$785,'Journal Entries'!$D$5:$D$785,"2100",'Journal Entries'!$J$5:$J$785,"<=43") -> 0 | O14: =SUMIFS('Journal Entries'!$I$5:$I$785,'Journal Entries'!$D$5:$D$785,"2100",'Journal Entries'!$J$5:$J$785,"<=45") -> 0
A15: 2300 | B15: Subscription line payable | C15: Cr | D15: =SUMIFS('Journal Entries'!$I$5:$I$785,'Journal Entries'!$D$5:$D$785,"2300",'Journal Entries'!$J$5:$J$785,"<=3") -> 0 | E15: =SUMIFS('Journal Entries'!$I$5:$I$785,'Journal Entries'!$D$5:$D$785,"2300",'Journal Entries'!$J$5:$J$785,"<=7") -> 0 | F15: =SUMIFS('Journal Entries'!$I$5:$I$785,'Journal Entries'!$D$5:$D$785,"2300",'Journal Entries'!$J$5:$J$785,"<=11") -> 0 | G15: =SUMIFS('Journal Entries'!$I$5:$I$785,'Journal Entries'!$D$5:$D$785,"2300",'Journal Entries'!$J$5:$J$785,"<=15") -> 0 | H15: =SUMIFS('Journal Entries'!$I$5:$I$785,'Journal Entries'!$D$5:$D$785,"2300",'Journal Entries'!$J$5:$J$785,"<=19") -> 0 | I15: =SUMIFS('Journal Entries'!$I$5:$I$785,'Journal Entries'!$D$5:$D$785,"2300",'Journal Entries'!$J$5:$J$785,"<=23") -> 0 | J15: =SUMIFS('Journal Entries'!$I$5:$I$785,'Journal Entries'!$D$5:$D$785,"2300",'Journal Entries'!$J$5:$J$785,"<=27") -> 0 | K15: =SUMIFS('Journal Entries'!$I$5:$I$785,'Journal Entries'!$D$5:$D$785,"2300",'Journal Entries'!$J$5:$J$785,"<=31") -> 0 | L15: =SUMIFS('Journal Entries'!$I$5:$I$785,'Journal Entries'!$D$5:$D$785,"2300",'Journal Entries'!$J$5:$J$785,"<=35") -> 0 | M15: =SUMIFS('Journal Entries'!$I$5:$I$785,'Journal Entries'!$D$5:$D$785,"2300",'Journal Entries'!$J$5:$J$785,"<=39") -> 0 | N15: =SUMIFS('Journal Entries'!$I$5:$I$785,'Journal Entries'!$D$5:$D$785,"2300",'Journal Entries'!$J$5:$J$785,"<=43") -> 0 | O15: =SUMIFS('Journal Entries'!$I$5:$I$785,'Journal Entries'!$D$5:$D$785,"2300",'Journal Entries'!$J$5:$J$785,"<=45") -> 0
A16: 2400 | B16: Distributions payable | C16: Cr | D16: =SUMIFS('Journal Entries'!$I$5:$I$785,'Journal Entries'!$D$5:$D$785,"2400",'Journal Entries'!$J$5:$J$785,"<=3") -> 0 | E16: =SUMIFS('Journal Entries'!$I$5:$I$785,'Journal Entries'!$D$5:$D$785,"2400",'Journal Entries'!$J$5:$J$785,"<=7") -> 0 | F16: =SUMIFS('Journal Entries'!$I$5:$I$785,'Journal Entries'!$D$5:$D$785,"2400",'Journal Entries'!$J$5:$J$785,"<=11") -> 0 | G16: =SUMIFS('Journal Entries'!$I$5:$I$785,'Journal Entries'!$D$5:$D$785,"2400",'Journal Entries'!$J$5:$J$785,"<=15") -> 0 | H16: =SUMIFS('Journal Entries'!$I$5:$I$785,'Journal Entries'!$D$5:$D$785,"2400",'Journal Entries'!$J$5:$J$785,"<=19") -> 0 | I16: =SUMIFS('Journal Entries'!$I$5:$I$785,'Journal Entries'!$D$5:$D$785,"2400",'Journal Entries'!$J$5:$J$785,"<=23") -> 0 | J16: =SUMIFS('Journal Entries'!$I$5:$I$785,'Journal Entries'!$D$5:$D$785,"2400",'Journal Entries'!$J$5:$J$785,"<=27") -> 0 | K16: =SUMIFS('Journal Entries'!$I$5:$I$785,'Journal Entries'!$D$5:$D$785,"2400",'Journal Entries'!$J$5:$J$785,"<=31") -> 0 | L16: =SUMIFS('Journal Entries'!$I$5:$I$785,'Journal Entries'!$D$5:$D$785,"2400",'Journal Entries'!$J$5:$J$785,"<=35") -> 0 | M16: =SUMIFS('Journal Entries'!$I$5:$I$785,'Journal Entries'!$D$5:$D$785,"2400",'Journal Entries'!$J$5:$J$785,"<=39") -> 0 | N16: =SUMIFS('Journal Entries'!$I$5:$I$785,'Journal Entries'!$D$5:$D$785,"2400",'Journal Entries'!$J$5:$J$785,"<=43") -> 0 | O16: =SUMIFS('Journal Entries'!$I$5:$I$785,'Journal Entries'!$D$5:$D$785,"2400",'Journal Entries'!$J$5:$J$785,"<=45") -> 0
A17: 3000 | B17: Partners' capital - contributions | C17: Cr | D17: =SUMIFS('Journal Entries'!$I$5:$I$785,'Journal Entries'!$D$5:$D$785,"3000",'Journal Entries'!$J$5:$J$785,"<=3") -> -47500000 | E17: =SUMIFS('Journal Entries'!$I$5:$I$785,'Journal Entries'!$D$5:$D$785,"3000",'Journal Entries'!$J$5:$J$785,"<=7") -> -107600000 | F17: =SUMIFS('Journal Entries'!$I$5:$I$785,'Journal Entries'!$D$5:$D$785,"3000",'Journal Entries'!$J$5:$J$785,"<=11") -> -162500000 | G17: =SUMIFS('Journal Entries'!$I$5:$I$785,'Journal Entries'!$D$5:$D$785,"3000",'Journal Entries'!$J$5:$J$785,"<=15") -> -193300000 | H17: =SUMIFS('Journal Entries'!$I$5:$I$785,'Journal Entries'!$D$5:$D$785,"3000",'Journal Entries'!$J$5:$J$785,"<=19") -> -206900000 | I17: =SUMIFS('Journal Entries'!$I$5:$I$785,'Journal Entries'!$D$5:$D$785,"3000",'Journal Entries'!$J$5:$J$785,"<=23") -> -209700000 | J17: =SUMIFS('Journal Entries'!$I$5:$I$785,'Journal Entries'!$D$5:$D$785,"3000",'Journal Entries'!$J$5:$J$785,"<=27") -> -211000000 | K17: =SUMIFS('Journal Entries'!$I$5:$I$785,'Journal Entries'!$D$5:$D$785,"3000",'Journal Entries'!$J$5:$J$785,"<=31") -> -212200000 | L17: =SUMIFS('Journal Entries'!$I$5:$I$785,'Journal Entries'!$D$5:$D$785,"3000",'Journal Entries'!$J$5:$J$785,"<=35") -> -213300000 | M17: =SUMIFS('Journal Entries'!$I$5:$I$785,'Journal Entries'!$D$5:$D$785,"3000",'Journal Entries'!$J$5:$J$785,"<=39") -> -213300000 | N17: =SUMIFS('Journal Entries'!$I$5:$I$785,'Journal Entries'!$D$5:$D$785,"3000",'Journal Entries'!$J$5:$J$785,"<=43") -> -213300000 | O17: =SUMIFS('Journal Entries'!$I$5:$I$785,'Journal Entries'!$D$5:$D$785,"3000",'Journal Entries'!$J$5:$J$785,"<=45") -> -213300000
A18: 3050 | B18: Partners' capital - offering costs charged against capital | C18: Cr | D18: =SUMIFS('Journal Entries'!$I$5:$I$785,'Journal Entries'!$D$5:$D$785,"3050",'Journal Entries'!$J$5:$J$785,"<=3") -> 900000 | E18: =SUMIFS('Journal Entries'!$I$5:$I$785,'Journal Entries'!$D$5:$D$785,"3050",'Journal Entries'!$J$5:$J$785,"<=7") -> 900000 | F18: =SUMIFS('Journal Entries'!$I$5:$I$785,'Journal Entries'!$D$5:$D$785,"3050",'Journal Entries'!$J$5:$J$785,"<=11") -> 900000 | G18: =SUMIFS('Journal Entries'!$I$5:$I$785,'Journal Entries'!$D$5:$D$785,"3050",'Journal Entries'!$J$5:$J$785,"<=15") -> 900000 | H18: =SUMIFS('Journal Entries'!$I$5:$I$785,'Journal Entries'!$D$5:$D$785,"3050",'Journal Entries'!$J$5:$J$785,"<=19") -> 900000 | I18: =SUMIFS('Journal Entries'!$I$5:$I$785,'Journal Entries'!$D$5:$D$785,"3050",'Journal Entries'!$J$5:$J$785,"<=23") -> 900000 | J18: =SUMIFS('Journal Entries'!$I$5:$I$785,'Journal Entries'!$D$5:$D$785,"3050",'Journal Entries'!$J$5:$J$785,"<=27") -> 900000 | K18: =SUMIFS('Journal Entries'!$I$5:$I$785,'Journal Entries'!$D$5:$D$785,"3050",'Journal Entries'!$J$5:$J$785,"<=31") -> 900000 | L18: =SUMIFS('Journal Entries'!$I$5:$I$785,'Journal Entries'!$D$5:$D$785,"3050",'Journal Entries'!$J$5:$J$785,"<=35") -> 900000 | M18: =SUMIFS('Journal Entries'!$I$5:$I$785,'Journal Entries'!$D$5:$D$785,"3050",'Journal Entries'!$J$5:$J$785,"<=39") -> 900000 | N18: =SUMIFS('Journal Entries'!$I$5:$I$785,'Journal Entries'!$D$5:$D$785,"3050",'Journal Entries'!$J$5:$J$785,"<=43") -> 900000 | O18: =SUMIFS('Journal Entries'!$I$5:$I$785,'Journal Entries'!$D$5:$D$785,"3050",'Journal Entries'!$J$5:$J$785,"<=45") -> 900000
A19: 3100 | B19: Partners' capital - distributions | C19: Cr | D19: =SUMIFS('Journal Entries'!$I$5:$I$785,'Journal Entries'!$D$5:$D$785,"3100",'Journal Entries'!$J$5:$J$785,"<=3") -> 0 | E19: =SUMIFS('Journal Entries'!$I$5:$I$785,'Journal Entries'!$D$5:$D$785,"3100",'Journal Entries'!$J$5:$J$785,"<=7") -> 0 | F19: =SUMIFS('Journal Entries'!$I$5:$I$785,'Journal Entries'!$D$5:$D$785,"3100",'Journal Entries'!$J$5:$J$785,"<=11") -> 0 | G19: =SUMIFS('Journal Entries'!$I$5:$I$785,'Journal Entries'!$D$5:$D$785,"3100",'Journal Entries'!$J$5:$J$785,"<=15") -> 0 | H19: =SUMIFS('Journal Entries'!$I$5:$I$785,'Journal Entries'!$D$5:$D$785,"3100",'Journal Entries'!$J$5:$J$785,"<=19") -> 0 | I19: =SUMIFS('Journal Entries'!$I$5:$I$785,'Journal Entries'!$D$5:$D$785,"3100",'Journal Entries'!$J$5:$J$785,"<=23") -> 115200000 | J19: =SUMIFS('Journal Entries'!$I$5:$I$785,'Journal Entries'!$D$5:$D$785,"3100",'Journal Entries'!$J$5:$J$785,"<=27") -> 141200000 | K19: =SUMIFS('Journal Entries'!$I$5:$I$785,'Journal Entries'!$D$5:$D$785,"3100",'Journal Entries'!$J$5:$J$785,"<=31") -> 141200000 | L19: =SUMIFS('Journal Entries'!$I$5:$I$785,'Journal Entries'!$D$5:$D$785,"3100",'Journal Entries'!$J$5:$J$785,"<=35") -> 230400000 | M19: =SUMIFS('Journal Entries'!$I$5:$I$785,'Journal Entries'!$D$5:$D$785,"3100",'Journal Entries'!$J$5:$J$785,"<=39") -> 348200000 | N19: =SUMIFS('Journal Entries'!$I$5:$I$785,'Journal Entries'!$D$5:$D$785,"3100",'Journal Entries'!$J$5:$J$785,"<=43") -> 409900000 | O19: =SUMIFS('Journal Entries'!$I$5:$I$785,'Journal Entries'!$D$5:$D$785,"3100",'Journal Entries'!$J$5:$J$785,"<=45") -> 4.1236728e+08
A20: 3900 | B20: Partners' capital - accumulated results | C20: Cr | D20: =SUMIFS('Journal Entries'!$I$5:$I$785,'Journal Entries'!$D$5:$D$785,"3900",'Journal Entries'!$J$5:$J$785,"<=3") -> 0 | E20: =SUMIFS('Journal Entries'!$I$5:$I$785,'Journal Entries'!$D$5:$D$785,"3900",'Journal Entries'!$J$5:$J$785,"<=7") -> 0 | F20: =SUMIFS('Journal Entries'!$I$5:$I$785,'Journal Entries'!$D$5:$D$785,"3900",'Journal Entries'!$J$5:$J$785,"<=11") -> 0 | G20: =SUMIFS('Journal Entries'!$I$5:$I$785,'Journal Entries'!$D$5:$D$785,"3900",'Journal Entries'!$J$5:$J$785,"<=15") -> 0 | H20: =SUMIFS('Journal Entries'!$I$5:$I$785,'Journal Entries'!$D$5:$D$785,"3900",'Journal Entries'!$J$5:$J$785,"<=19") -> 0 | I20: =SUMIFS('Journal Entries'!$I$5:$I$785,'Journal Entries'!$D$5:$D$785,"3900",'Journal Entries'!$J$5:$J$785,"<=23") -> 0 | J20: =SUMIFS('Journal Entries'!$I$5:$I$785,'Journal Entries'!$D$5:$D$785,"3900",'Journal Entries'!$J$5:$J$785,"<=27") -> 0 | K20: =SUMIFS('Journal Entries'!$I$5:$I$785,'Journal Entries'!$D$5:$D$785,"3900",'Journal Entries'!$J$5:$J$785,"<=31") -> 0 | L20: =SUMIFS('Journal Entries'!$I$5:$I$785,'Journal Entries'!$D$5:$D$785,"3900",'Journal Entries'!$J$5:$J$785,"<=35") -> 0 | M20: =SUMIFS('Journal Entries'!$I$5:$I$785,'Journal Entries'!$D$5:$D$785,"3900",'Journal Entries'!$J$5:$J$785,"<=39") -> 0 | N20: =SUMIFS('Journal Entries'!$I$5:$I$785,'Journal Entries'!$D$5:$D$785,"3900",'Journal Entries'!$J$5:$J$785,"<=43") -> 0 | O20: =SUMIFS('Journal Entries'!$I$5:$I$785,'Journal Entries'!$D$5:$D$785,"3900",'Journal Entries'!$J$5:$J$785,"<=45") -> 0
A21: 4000 | B21: Interest income - PIK | C21: Cr | D21: =SUMIFS('Journal Entries'!$I$5:$I$785,'Journal Entries'!$D$5:$D$785,"4000",'Journal Entries'!$J$5:$J$785,"<=3") -> 0 | E21: =SUMIFS('Journal Entries'!$I$5:$I$785,'Journal Entries'!$D$5:$D$785,"4000",'Journal Entries'!$J$5:$J$785,"<=7") -> 0 | F21: =SUMIFS('Journal Entries'!$I$5:$I$785,'Journal Entries'!$D$5:$D$785,"4000",'Journal Entries'!$J$5:$J$785,"<=11") -> 0 | G21: =SUMIFS('Journal Entries'!$I$5:$I$785,'Journal Entries'!$D$5:$D$785,"4000",'Journal Entries'!$J$5:$J$785,"<=15") -> -1298178 | H21: =SUMIFS('Journal Entries'!$I$5:$I$785,'Journal Entries'!$D$5:$D$785,"4000",'Journal Entries'!$J$5:$J$785,"<=19") -> -3218234.1 | I21: =SUMIFS('Journal Entries'!$I$5:$I$785,'Journal Entries'!$D$5:$D$785,"4000",'Journal Entries'!$J$5:$J$785,"<=23") -> -5379274.2 | J21: =SUMIFS('Journal Entries'!$I$5:$I$785,'Journal Entries'!$D$5:$D$785,"4000",'Journal Entries'!$J$5:$J$785,"<=27") -> -7811543.8 | K21: =SUMIFS('Journal Entries'!$I$5:$I$785,'Journal Entries'!$D$5:$D$785,"4000",'Journal Entries'!$J$5:$J$785,"<=31") -> -10549085 | L21: =SUMIFS('Journal Entries'!$I$5:$I$785,'Journal Entries'!$D$5:$D$785,"4000",'Journal Entries'!$J$5:$J$785,"<=35") -> -13630211 | M21: =SUMIFS('Journal Entries'!$I$5:$I$785,'Journal Entries'!$D$5:$D$785,"4000",'Journal Entries'!$J$5:$J$785,"<=39") -> -16192278 | N21: =SUMIFS('Journal Entries'!$I$5:$I$785,'Journal Entries'!$D$5:$D$785,"4000",'Journal Entries'!$J$5:$J$785,"<=43") -> -16192278 | O21: =SUMIFS('Journal Entries'!$I$5:$I$785,'Journal Entries'!$D$5:$D$785,"4000",'Journal Entries'!$J$5:$J$785,"<=45") -> -16192278
A22: 4010 | B22: Interest income - other | C22: Cr | D22: =SUMIFS('Journal Entries'!$I$5:$I$785,'Journal Entries'!$D$5:$D$785,"4010",'Journal Entries'!$J$5:$J$785,"<=3") -> 0 | E22: =SUMIFS('Journal Entries'!$I$5:$I$785,'Journal Entries'!$D$5:$D$785,"4010",'Journal Entries'!$J$5:$J$785,"<=7") -> 0 | F22: =SUMIFS('Journal Entries'!$I$5:$I$785,'Journal Entries'!$D$5:$D$785,"4010",'Journal Entries'!$J$5:$J$785,"<=11") -> 0 | G22: =SUMIFS('Journal Entries'!$I$5:$I$785,'Journal Entries'!$D$5:$D$785,"4010",'Journal Entries'!$J$5:$J$785,"<=15") -> 0 | H22: =SUMIFS('Journal Entries'!$I$5:$I$785,'Journal Entries'!$D$5:$D$785,"4010",'Journal Entries'!$J$5:$J$785,"<=19") -> 0 | I22: =SUMIFS('Journal Entries'!$I$5:$I$785,'Journal Entries'!$D$5:$D$785,"4010",'Journal Entries'!$J$5:$J$785,"<=23") -> 0 | J22: =SUMIFS('Journal Entries'!$I$5:$I$785,'Journal Entries'!$D$5:$D$785,"4010",'Journal Entries'!$J$5:$J$785,"<=27") -> 0 | K22: =SUMIFS('Journal Entries'!$I$5:$I$785,'Journal Entries'!$D$5:$D$785,"4010",'Journal Entries'!$J$5:$J$785,"<=31") -> 0 | L22: =SUMIFS('Journal Entries'!$I$5:$I$785,'Journal Entries'!$D$5:$D$785,"4010",'Journal Entries'!$J$5:$J$785,"<=35") -> 0 | M22: =SUMIFS('Journal Entries'!$I$5:$I$785,'Journal Entries'!$D$5:$D$785,"4010",'Journal Entries'!$J$5:$J$785,"<=39") -> 0 | N22: =SUMIFS('Journal Entries'!$I$5:$I$785,'Journal Entries'!$D$5:$D$785,"4010",'Journal Entries'!$J$5:$J$785,"<=43") -> 0 | O22: =SUMIFS('Journal Entries'!$I$5:$I$785,'Journal Entries'!$D$5:$D$785,"4010",'Journal Entries'!$J$5:$J$785,"<=45") -> 0
A23: 4030 | B23: Other income - monitoring fees | C23: Cr | D23: =SUMIFS('Journal Entries'!$I$5:$I$785,'Journal Entries'!$D$5:$D$785,"4030",'Journal Entries'!$J$5:$J$785,"<=3") -> 0 | E23: =SUMIFS('Journal Entries'!$I$5:$I$785,'Journal Entries'!$D$5:$D$785,"4030",'Journal Entries'!$J$5:$J$785,"<=7") -> 0 | F23: =SUMIFS('Journal Entries'!$I$5:$I$785,'Journal Entries'!$D$5:$D$785,"4030",'Journal Entries'!$J$5:$J$785,"<=11") -> 0 | G23: =SUMIFS('Journal Entries'!$I$5:$I$785,'Journal Entries'!$D$5:$D$785,"4030",'Journal Entries'!$J$5:$J$785,"<=15") -> 0 | H23: =SUMIFS('Journal Entries'!$I$5:$I$785,'Journal Entries'!$D$5:$D$785,"4030",'Journal Entries'!$J$5:$J$785,"<=19") -> 0 | I23: =SUMIFS('Journal Entries'!$I$5:$I$785,'Journal Entries'!$D$5:$D$785,"4030",'Journal Entries'!$J$5:$J$785,"<=23") -> 0 | J23: =SUMIFS('Journal Entries'!$I$5:$I$785,'Journal Entries'!$D$5:$D$785,"4030",'Journal Entries'!$J$5:$J$785,"<=27") -> 0 | K23: =SUMIFS('Journal Entries'!$I$5:$I$785,'Journal Entries'!$D$5:$D$785,"4030",'Journal Entries'!$J$5:$J$785,"<=31") -> 0 | L23: =SUMIFS('Journal Entries'!$I$5:$I$785,'Journal Entries'!$D$5:$D$785,"4030",'Journal Entries'!$J$5:$J$785,"<=35") -> 0 | M23: =SUMIFS('Journal Entries'!$I$5:$I$785,'Journal Entries'!$D$5:$D$785,"4030",'Journal Entries'!$J$5:$J$785,"<=39") -> 0 | N23: =SUMIFS('Journal Entries'!$I$5:$I$785,'Journal Entries'!$D$5:$D$785,"4030",'Journal Entries'!$J$5:$J$785,"<=43") -> 0 | O23: =SUMIFS('Journal Entries'!$I$5:$I$785,'Journal Entries'!$D$5:$D$785,"4030",'Journal Entries'!$J$5:$J$785,"<=45") -> 0
A24: 5000 | B24: Management fee | C24: Dr | D24: =SUMIFS('Journal Entries'!$I$5:$I$785,'Journal Entries'!$D$5:$D$785,"5000",'Journal Entries'!$J$5:$J$785,"<=3") -> 2600000 | E24: =SUMIFS('Journal Entries'!$I$5:$I$785,'Journal Entries'!$D$5:$D$785,"5000",'Journal Entries'!$J$5:$J$785,"<=7") -> 7150000 | F24: =SUMIFS('Journal Entries'!$I$5:$I$785,'Journal Entries'!$D$5:$D$785,"5000",'Journal Entries'!$J$5:$J$785,"<=11") -> 12050000 | G24: =SUMIFS('Journal Entries'!$I$5:$I$785,'Journal Entries'!$D$5:$D$785,"5000",'Journal Entries'!$J$5:$J$785,"<=15") -> 16950000 | H24: =SUMIFS('Journal Entries'!$I$5:$I$785,'Journal Entries'!$D$5:$D$785,"5000",'Journal Entries'!$J$5:$J$785,"<=19") -> 21850000 | I24: =SUMIFS('Journal Entries'!$I$5:$I$785,'Journal Entries'!$D$5:$D$785,"5000",'Journal Entries'!$J$5:$J$785,"<=23") -> 26750000 | J24: =SUMIFS('Journal Entries'!$I$5:$I$785,'Journal Entries'!$D$5:$D$785,"5000",'Journal Entries'!$J$5:$J$785,"<=27") -> 30260000 | K24: =SUMIFS('Journal Entries'!$I$5:$I$785,'Journal Entries'!$D$5:$D$785,"5000",'Journal Entries'!$J$5:$J$785,"<=31") -> 32380000 | L24: =SUMIFS('Journal Entries'!$I$5:$I$785,'Journal Entries'!$D$5:$D$785,"5000",'Journal Entries'!$J$5:$J$785,"<=35") -> 33975000 | M24: =SUMIFS('Journal Entries'!$I$5:$I$785,'Journal Entries'!$D$5:$D$785,"5000",'Journal Entries'!$J$5:$J$785,"<=39") -> 34850000 | N24: =SUMIFS('Journal Entries'!$I$5:$I$785,'Journal Entries'!$D$5:$D$785,"5000",'Journal Entries'!$J$5:$J$785,"<=43") -> 34940000 | O24: =SUMIFS('Journal Entries'!$I$5:$I$785,'Journal Entries'!$D$5:$D$785,"5000",'Journal Entries'!$J$5:$J$785,"<=45") -> 34940000
A25: 5010 | B25: Management fee offset | C25: Dr | D25: =SUMIFS('Journal Entries'!$I$5:$I$785,'Journal Entries'!$D$5:$D$785,"5010",'Journal Entries'!$J$5:$J$785,"<=3") -> 0 | E25: =SUMIFS('Journal Entries'!$I$5:$I$785,'Journal Entries'!$D$5:$D$785,"5010",'Journal Entries'!$J$5:$J$785,"<=7") -> 0 | F25: =SUMIFS('Journal Entries'!$I$5:$I$785,'Journal Entries'!$D$5:$D$785,"5010",'Journal Entries'!$J$5:$J$785,"<=11") -> -350000 | G25: =SUMIFS('Journal Entries'!$I$5:$I$785,'Journal Entries'!$D$5:$D$785,"5010",'Journal Entries'!$J$5:$J$785,"<=15") -> -750000 | H25: =SUMIFS('Journal Entries'!$I$5:$I$785,'Journal Entries'!$D$5:$D$785,"5010",'Journal Entries'!$J$5:$J$785,"<=19") -> -1150000 | I25: =SUMIFS('Journal Entries'!$I$5:$I$785,'Journal Entries'!$D$5:$D$785,"5010",'Journal Entries'!$J$5:$J$785,"<=23") -> -1400000 | J25: =SUMIFS('Journal Entries'!$I$5:$I$785,'Journal Entries'!$D$5:$D$785,"5010",'Journal Entries'!$J$5:$J$785,"<=27") -> -1400000 | K25: =SUMIFS('Journal Entries'!$I$5:$I$785,'Journal Entries'!$D$5:$D$785,"5010",'Journal Entries'!$J$5:$J$785,"<=31") -> -1400000 | L25: =SUMIFS('Journal Entries'!$I$5:$I$785,'Journal Entries'!$D$5:$D$785,"5010",'Journal Entries'!$J$5:$J$785,"<=35") -> -1400000 | M25: =SUMIFS('Journal Entries'!$I$5:$I$785,'Journal Entries'!$D$5:$D$785,"5010",'Journal Entries'!$J$5:$J$785,"<=39") -> -1400000 | N25: =SUMIFS('Journal Entries'!$I$5:$I$785,'Journal Entries'!$D$5:$D$785,"5010",'Journal Entries'!$J$5:$J$785,"<=43") -> -1400000 | O25: =SUMIFS('Journal Entries'!$I$5:$I$785,'Journal Entries'!$D$5:$D$785,"5010",'Journal Entries'!$J$5:$J$785,"<=45") -> -1400000
A26: 5100 | B26: Organizational costs | C26: Dr | D26: =SUMIFS('Journal Entries'!$I$5:$I$785,'Journal Entries'!$D$5:$D$785,"5100",'Journal Entries'!$J$5:$J$785,"<=3") -> 1200000 | E26: =SUMIFS('Journal Entries'!$I$5:$I$785,'Journal Entries'!$D$5:$D$785,"5100",'Journal Entries'!$J$5:$J$785,"<=7") -> 1200000 | F26: =SUMIFS('Journal Entries'!$I$5:$I$785,'Journal Entries'!$D$5:$D$785,"5100",'Journal Entries'!$J$5:$J$785,"<=11") -> 1200000 | G26: =SUMIFS('Journal Entries'!$I$5:$I$785,'Journal Entries'!$D$5:$D$785,"5100",'Journal Entries'!$J$5:$J$785,"<=15") -> 1200000 | H26: =SUMIFS('Journal Entries'!$I$5:$I$785,'Journal Entries'!$D$5:$D$785,"5100",'Journal Entries'!$J$5:$J$785,"<=19") -> 1200000 | I26: =SUMIFS('Journal Entries'!$I$5:$I$785,'Journal Entries'!$D$5:$D$785,"5100",'Journal Entries'!$J$5:$J$785,"<=23") -> 1200000 | J26: =SUMIFS('Journal Entries'!$I$5:$I$785,'Journal Entries'!$D$5:$D$785,"5100",'Journal Entries'!$J$5:$J$785,"<=27") -> 1200000 | K26: =SUMIFS('Journal Entries'!$I$5:$I$785,'Journal Entries'!$D$5:$D$785,"5100",'Journal Entries'!$J$5:$J$785,"<=31") -> 1200000 | L26: =SUMIFS('Journal Entries'!$I$5:$I$785,'Journal Entries'!$D$5:$D$785,"5100",'Journal Entries'!$J$5:$J$785,"<=35") -> 1200000 | M26: =SUMIFS('Journal Entries'!$I$5:$I$785,'Journal Entries'!$D$5:$D$785,"5100",'Journal Entries'!$J$5:$J$785,"<=39") -> 1200000 | N26: =SUMIFS('Journal Entries'!$I$5:$I$785,'Journal Entries'!$D$5:$D$785,"5100",'Journal Entries'!$J$5:$J$785,"<=43") -> 1200000 | O26: =SUMIFS('Journal Entries'!$I$5:$I$785,'Journal Entries'!$D$5:$D$785,"5100",'Journal Entries'!$J$5:$J$785,"<=45") -> 1200000
A27: 5110 | B27: Amortization of deferred offering costs | C27: Dr | D27: =SUMIFS('Journal Entries'!$I$5:$I$785,'Journal Entries'!$D$5:$D$785,"5110",'Journal Entries'!$J$5:$J$785,"<=3") -> 0 | E27: =SUMIFS('Journal Entries'!$I$5:$I$785,'Journal Entries'!$D$5:$D$785,"5110",'Journal Entries'!$J$5:$J$785,"<=7") -> 0 | F27: =SUMIFS('Journal Entries'!$I$5:$I$785,'Journal Entries'!$D$5:$D$785,"5110",'Journal Entries'!$J$5:$J$785,"<=11") -> 0 | G27: =SUMIFS('Journal Entries'!$I$5:$I$785,'Journal Entries'!$D$5:$D$785,"5110",'Journal Entries'!$J$5:$J$785,"<=15") -> 0 | H27: =SUMIFS('Journal Entries'!$I$5:$I$785,'Journal Entries'!$D$5:$D$785,"5110",'Journal Entries'!$J$5:$J$785,"<=19") -> 0 | I27: =SUMIFS('Journal Entries'!$I$5:$I$785,'Journal Entries'!$D$5:$D$785,"5110",'Journal Entries'!$J$5:$J$785,"<=23") -> 0 | J27: =SUMIFS('Journal Entries'!$I$5:$I$785,'Journal Entries'!$D$5:$D$785,"5110",'Journal Entries'!$J$5:$J$785,"<=27") -> 0 | K27: =SUMIFS('Journal Entries'!$I$5:$I$785,'Journal Entries'!$D$5:$D$785,"5110",'Journal Entries'!$J$5:$J$785,"<=31") -> 0 | L27: =SUMIFS('Journal Entries'!$I$5:$I$785,'Journal Entries'!$D$5:$D$785,"5110",'Journal Entries'!$J$5:$J$785,"<=35") -> 0 | M27: =SUMIFS('Journal Entries'!$I$5:$I$785,'Journal Entries'!$D$5:$D$785,"5110",'Journal Entries'!$J$5:$J$785,"<=39") -> 0 | N27: =SUMIFS('Journal Entries'!$I$5:$I$785,'Journal Entries'!$D$5:$D$785,"5110",'Journal Entries'!$J$5:$J$785,"<=43") -> 0 | O27: =SUMIFS('Journal Entries'!$I$5:$I$785,'Journal Entries'!$D$5:$D$785,"5110",'Journal Entries'!$J$5:$J$785,"<=45") -> 0
A28: 5200 | B28: Professional fees - audit and tax | C28: Dr | D28: =SUMIFS('Journal Entries'!$I$5:$I$785,'Journal Entries'!$D$5:$D$785,"5200",'Journal Entries'!$J$5:$J$785,"<=3") -> 120000 | E28: =SUMIFS('Journal Entries'!$I$5:$I$785,'Journal Entries'!$D$5:$D$785,"5200",'Journal Entries'!$J$5:$J$785,"<=7") -> 300000 | F28: =SUMIFS('Journal Entries'!$I$5:$I$785,'Journal Entries'!$D$5:$D$785,"5200",'Journal Entries'!$J$5:$J$785,"<=11") -> 480000 | G28: =SUMIFS('Journal Entries'!$I$5:$I$785,'Journal Entries'!$D$5:$D$785,"5200",'Journal Entries'!$J$5:$J$785,"<=15") -> 660000 | H28: =SUMIFS('Journal Entries'!$I$5:$I$785,'Journal Entries'!$D$5:$D$785,"5200",'Journal Entries'!$J$5:$J$785,"<=19") -> 840000 | I28: =SUMIFS('Journal Entries'!$I$5:$I$785,'Journal Entries'!$D$5:$D$785,"5200",'Journal Entries'!$J$5:$J$785,"<=23") -> 1020000 | J28: =SUMIFS('Journal Entries'!$I$5:$I$785,'Journal Entries'!$D$5:$D$785,"5200",'Journal Entries'!$J$5:$J$785,"<=27") -> 1212000 | K28: =SUMIFS('Journal Entries'!$I$5:$I$785,'Journal Entries'!$D$5:$D$785,"5200",'Journal Entries'!$J$5:$J$785,"<=31") -> 1404000 | L28: =SUMIFS('Journal Entries'!$I$5:$I$785,'Journal Entries'!$D$5:$D$785,"5200",'Journal Entries'!$J$5:$J$785,"<=35") -> 1596000 | M28: =SUMIFS('Journal Entries'!$I$5:$I$785,'Journal Entries'!$D$5:$D$785,"5200",'Journal Entries'!$J$5:$J$785,"<=39") -> 1788000 | N28: =SUMIFS('Journal Entries'!$I$5:$I$785,'Journal Entries'!$D$5:$D$785,"5200",'Journal Entries'!$J$5:$J$785,"<=43") -> 1980000 | O28: =SUMIFS('Journal Entries'!$I$5:$I$785,'Journal Entries'!$D$5:$D$785,"5200",'Journal Entries'!$J$5:$J$785,"<=45") -> 2076000
A29: 5210 | B29: Professional fees - legal | C29: Dr | D29: =SUMIFS('Journal Entries'!$I$5:$I$785,'Journal Entries'!$D$5:$D$785,"5210",'Journal Entries'!$J$5:$J$785,"<=3") -> 140000 | E29: =SUMIFS('Journal Entries'!$I$5:$I$785,'Journal Entries'!$D$5:$D$785,"5210",'Journal Entries'!$J$5:$J$785,"<=7") -> 212000 | F29: =SUMIFS('Journal Entries'!$I$5:$I$785,'Journal Entries'!$D$5:$D$785,"5210",'Journal Entries'!$J$5:$J$785,"<=11") -> 284000 | G29: =SUMIFS('Journal Entries'!$I$5:$I$785,'Journal Entries'!$D$5:$D$785,"5210",'Journal Entries'!$J$5:$J$785,"<=15") -> 356000 | H29: =SUMIFS('Journal Entries'!$I$5:$I$785,'Journal Entries'!$D$5:$D$785,"5210",'Journal Entries'!$J$5:$J$785,"<=19") -> 428000 | I29: =SUMIFS('Journal Entries'!$I$5:$I$785,'Journal Entries'!$D$5:$D$785,"5210",'Journal Entries'!$J$5:$J$785,"<=23") -> 500000 | J29: =SUMIFS('Journal Entries'!$I$5:$I$785,'Journal Entries'!$D$5:$D$785,"5210",'Journal Entries'!$J$5:$J$785,"<=27") -> 560000 | K29: =SUMIFS('Journal Entries'!$I$5:$I$785,'Journal Entries'!$D$5:$D$785,"5210",'Journal Entries'!$J$5:$J$785,"<=31") -> 620000 | L29: =SUMIFS('Journal Entries'!$I$5:$I$785,'Journal Entries'!$D$5:$D$785,"5210",'Journal Entries'!$J$5:$J$785,"<=35") -> 680000 | M29: =SUMIFS('Journal Entries'!$I$5:$I$785,'Journal Entries'!$D$5:$D$785,"5210",'Journal Entries'!$J$5:$J$785,"<=39") -> 740000 | N29: =SUMIFS('Journal Entries'!$I$5:$I$785,'Journal Entries'!$D$5:$D$785,"5210",'Journal Entries'!$J$5:$J$785,"<=43") -> 800000 | O29: =SUMIFS('Journal Entries'!$I$5:$I$785,'Journal Entries'!$D$5:$D$785,"5210",'Journal Entries'!$J$5:$J$785,"<=45") -> 830000
A30: 5300 | B30: Fund administration fees | C30: Dr | D30: =SUMIFS('Journal Entries'!$I$5:$I$785,'Journal Entries'!$D$5:$D$785,"5300",'Journal Entries'!$J$5:$J$785,"<=3") -> 180000 | E30: =SUMIFS('Journal Entries'!$I$5:$I$785,'Journal Entries'!$D$5:$D$785,"5300",'Journal Entries'!$J$5:$J$785,"<=7") -> 430000 | F30: =SUMIFS('Journal Entries'!$I$5:$I$785,'Journal Entries'!$D$5:$D$785,"5300",'Journal Entries'!$J$5:$J$785,"<=11") -> 680000 | G30: =SUMIFS('Journal Entries'!$I$5:$I$785,'Journal Entries'!$D$5:$D$785,"5300",'Journal Entries'!$J$5:$J$785,"<=15") -> 930000 | H30: =SUMIFS('Journal Entries'!$I$5:$I$785,'Journal Entries'!$D$5:$D$785,"5300",'Journal Entries'!$J$5:$J$785,"<=19") -> 1180000 | I30: =SUMIFS('Journal Entries'!$I$5:$I$785,'Journal Entries'!$D$5:$D$785,"5300",'Journal Entries'!$J$5:$J$785,"<=23") -> 1430000 | J30: =SUMIFS('Journal Entries'!$I$5:$I$785,'Journal Entries'!$D$5:$D$785,"5300",'Journal Entries'!$J$5:$J$785,"<=27") -> 1650000 | K30: =SUMIFS('Journal Entries'!$I$5:$I$785,'Journal Entries'!$D$5:$D$785,"5300",'Journal Entries'!$J$5:$J$785,"<=31") -> 1870000 | L30: =SUMIFS('Journal Entries'!$I$5:$I$785,'Journal Entries'!$D$5:$D$785,"5300",'Journal Entries'!$J$5:$J$785,"<=35") -> 2090000 | M30: =SUMIFS('Journal Entries'!$I$5:$I$785,'Journal Entries'!$D$5:$D$785,"5300",'Journal Entries'!$J$5:$J$785,"<=39") -> 2310000 | N30: =SUMIFS('Journal Entries'!$I$5:$I$785,'Journal Entries'!$D$5:$D$785,"5300",'Journal Entries'!$J$5:$J$785,"<=43") -> 2530000 | O30: =SUMIFS('Journal Entries'!$I$5:$I$785,'Journal Entries'!$D$5:$D$785,"5300",'Journal Entries'!$J$5:$J$785,"<=45") -> 2640000
